2021-04-29 18:20:18,809 DEBUG asyncio Using selector: EpollSelector
2021-04-29 18:20:23,566 DEBUG quic [0000000000000002] Network path ('127.0.0.1', 4988) discovered
2021-04-29 18:20:23,569 DEBUG quic [0000000000000002] QuicConnectionState.FIRSTFLIGHT -> QuicConnectionState.CONNECTED
2021-04-29 18:20:23,583 DEBUG quic [0000000000000002] TLS State.SERVER_EXPECT_CLIENT_HELLO -> State.SERVER_EXPECT_FINISHED
2021-04-29 18:20:23,890 DEBUG quic [0000000000000002] Discarding epoch Epoch.INITIAL
2021-04-29 18:20:23,891 DEBUG quic [0000000000000002] TLS State.SERVER_EXPECT_FINISHED -> State.SERVER_POST_HANDSHAKE
2021-04-29 18:20:23,891 DEBUG quic [0000000000000002] Discarding epoch Epoch.HANDSHAKE
2021-04-29 18:20:23,892 INFO quic [0000000000000002] ALPN negotiated protocol hq-29
2021-04-29 18:20:23,892 INFO quic [0000000000000002] Connection close code 0x5FB0, reason 
2021-04-29 18:20:23,892 DEBUG quic [0000000000000002] QuicConnectionState.CONNECTED -> QuicConnectionState.DRAINING
2021-04-29 18:20:25,392 DEBUG quic [0000000000000002] Discarding epoch Epoch.ONE_RTT
2021-04-29 18:20:25,392 DEBUG quic [0000000000000002] QuicConnectionState.DRAINING -> QuicConnectionState.TERMINATED
2021-04-29 18:20:25,967 DEBUG quic [402802adf76028d5] Network path ('127.0.0.1', 4988) discovered
2021-04-29 18:20:25,969 DEBUG quic [402802adf76028d5] Payload decryption failed
2021-04-29 18:20:26,596 DEBUG quic [0000000000000002] Network path ('127.0.0.1', 4988) discovered
2021-04-29 18:20:26,598 DEBUG quic [0000000000000002] QuicConnectionState.FIRSTFLIGHT -> QuicConnectionState.CONNECTED
2021-04-29 18:20:26,598 INFO quic [0000000000000002] Connection close code 0xE8BE, reason 5
2021-04-29 18:20:26,598 DEBUG quic [0000000000000002] QuicConnectionState.CONNECTED -> QuicConnectionState.DRAINING
2021-04-29 18:20:27,016 ERROR asyncio Exception in callback _SelectorDatagramTransport._read_ready()
handle: <Handle _SelectorDatagramTransport._read_ready()>
Traceback (most recent call last):
  File "/usr/lib/python3.6/asyncio/events.py", line 145, in _run
    self._callback(*self._args)
  File "/usr/lib/python3.6/asyncio/selector_events.py", line 1068, in _read_ready
    self._protocol.datagram_received(data, addr)
  File "/quic/aioquic/src/aioquic/asyncio/server.py", line 149, in datagram_received
    protocol.datagram_received(data, addr)
  File "/quic/aioquic/src/aioquic/asyncio/protocol.py", line 135, in datagram_received
    self._quic.receive_datagram(cast(bytes, data), addr, now=self._loop.time())
  File "/quic/aioquic/src/aioquic/quic/connection.py", line 793, in receive_datagram
    ), "first packet must be INITIAL"
AssertionError: first packet must be INITIAL
2021-04-29 18:20:27,645 ERROR asyncio Exception in callback _SelectorDatagramTransport._read_ready()
handle: <Handle _SelectorDatagramTransport._read_ready()>
Traceback (most recent call last):
  File "/usr/lib/python3.6/asyncio/events.py", line 145, in _run
    self._callback(*self._args)
  File "/usr/lib/python3.6/asyncio/selector_events.py", line 1068, in _read_ready
    self._protocol.datagram_received(data, addr)
  File "/quic/aioquic/src/aioquic/asyncio/server.py", line 149, in datagram_received
    protocol.datagram_received(data, addr)
  File "/quic/aioquic/src/aioquic/asyncio/protocol.py", line 135, in datagram_received
    self._quic.receive_datagram(cast(bytes, data), addr, now=self._loop.time())
  File "/quic/aioquic/src/aioquic/quic/connection.py", line 793, in receive_datagram
    ), "first packet must be INITIAL"
AssertionError: first packet must be INITIAL
2021-04-29 18:20:28,096 DEBUG quic [0000000000000002] Discarding epoch Epoch.INITIAL
2021-04-29 18:20:28,097 DEBUG quic [0000000000000002] Discarding epoch Epoch.HANDSHAKE
2021-04-29 18:20:28,097 DEBUG quic [0000000000000002] Discarding epoch Epoch.ONE_RTT
2021-04-29 18:20:28,097 DEBUG quic [0000000000000002] QuicConnectionState.DRAINING -> QuicConnectionState.TERMINATED
2021-04-29 18:20:28,154 ERROR asyncio Exception in callback _SelectorDatagramTransport._read_ready()
handle: <Handle _SelectorDatagramTransport._read_ready()>
Traceback (most recent call last):
  File "/usr/lib/python3.6/asyncio/events.py", line 145, in _run
    self._callback(*self._args)
  File "/usr/lib/python3.6/asyncio/selector_events.py", line 1068, in _read_ready
    self._protocol.datagram_received(data, addr)
  File "/quic/aioquic/src/aioquic/asyncio/server.py", line 149, in datagram_received
    protocol.datagram_received(data, addr)
  File "/quic/aioquic/src/aioquic/asyncio/protocol.py", line 135, in datagram_received
    self._quic.receive_datagram(cast(bytes, data), addr, now=self._loop.time())
  File "/quic/aioquic/src/aioquic/quic/connection.py", line 793, in receive_datagram
    ), "first packet must be INITIAL"
AssertionError: first packet must be INITIAL
2021-04-29 18:20:28,400 DEBUG quic [402802adf76028d5] Payload decryption failed
