2021-03-27 18:08:57,543 DEBUG asyncio Using selector: EpollSelector
2021-03-27 18:09:02,361 DEBUG quic [0000000000000001] Network path ('127.0.0.1', 4987) discovered
2021-03-27 18:09:02,364 DEBUG quic [0000000000000001] QuicConnectionState.FIRSTFLIGHT -> QuicConnectionState.CONNECTED
2021-03-27 18:09:02,378 DEBUG quic [0000000000000001] TLS State.SERVER_EXPECT_CLIENT_HELLO -> State.SERVER_EXPECT_FINISHED
2021-03-27 18:09:02,688 DEBUG quic [0000000000000001] Discarding epoch Epoch.INITIAL
2021-03-27 18:09:02,690 DEBUG quic [0000000000000001] TLS State.SERVER_EXPECT_FINISHED -> State.SERVER_POST_HANDSHAKE
2021-03-27 18:09:02,691 DEBUG quic [0000000000000001] Discarding epoch Epoch.HANDSHAKE
2021-03-27 18:09:02,691 INFO quic [0000000000000001] ALPN negotiated protocol hq-29
2021-03-27 18:09:02,691 DEBUG quic [0000000000000001] Network path ('127.0.0.1', 4987) validated by handshake
2021-03-27 18:09:03,069 DEBUG quic [de7fcfc0507f0aa0] Network path ('127.0.0.1', 4987) discovered
2021-03-27 18:09:03,070 DEBUG quic [de7fcfc0507f0aa0] Payload decryption failed
2021-03-27 18:09:03,292 ERROR asyncio Exception in callback _SelectorDatagramTransport._read_ready()
handle: <Handle _SelectorDatagramTransport._read_ready()>
Traceback (most recent call last):
  File "/usr/lib/python3.6/asyncio/events.py", line 145, in _run
    self._callback(*self._args)
  File "/usr/lib/python3.6/asyncio/selector_events.py", line 1068, in _read_ready
    self._protocol.datagram_received(data, addr)
  File "/quic/aioquic/src/aioquic/asyncio/server.py", line 149, in datagram_received
    protocol.datagram_received(data, addr)
  File "/quic/aioquic/src/aioquic/asyncio/protocol.py", line 135, in datagram_received
    self._quic.receive_datagram(cast(bytes, data), addr, now=self._loop.time())
  File "/quic/aioquic/src/aioquic/quic/connection.py", line 793, in receive_datagram
    ), "first packet must be INITIAL"
AssertionError: first packet must be INITIAL
2021-03-27 18:09:03,600 ERROR asyncio Exception in callback _SelectorDatagramTransport._read_ready()
handle: <Handle _SelectorDatagramTransport._read_ready()>
Traceback (most recent call last):
  File "/usr/lib/python3.6/asyncio/events.py", line 145, in _run
    self._callback(*self._args)
  File "/usr/lib/python3.6/asyncio/selector_events.py", line 1068, in _read_ready
    self._protocol.datagram_received(data, addr)
  File "/quic/aioquic/src/aioquic/asyncio/server.py", line 149, in datagram_received
    protocol.datagram_received(data, addr)
  File "/quic/aioquic/src/aioquic/asyncio/protocol.py", line 135, in datagram_received
    self._quic.receive_datagram(cast(bytes, data), addr, now=self._loop.time())
  File "/quic/aioquic/src/aioquic/quic/connection.py", line 793, in receive_datagram
    ), "first packet must be INITIAL"
AssertionError: first packet must be INITIAL
2021-03-27 18:09:03,646 DEBUG quic [0000000000000001] Loss detection triggered
2021-03-27 18:09:03,646 DEBUG quic [0000000000000001] Sending PING (probe) in packet 4
2021-03-27 18:09:03,897 DEBUG quic [0000000000000001] Network path ('127.0.0.1', 4988) discovered
2021-03-27 18:09:03,898 DEBUG quic [0000000000000001] Received PING (probe) response
2021-03-27 18:09:03,898 DEBUG quic [0000000000000001] Peer switching to CID de7fcfc0507f0aa0 (1)
2021-03-27 18:09:03,898 DEBUG quic [0000000000000001] Network path ('127.0.0.1', 4988) promoted
2021-03-27 18:09:04,313 DEBUG quic [0000000000000001] Stream 16 created by peer
2021-03-27 18:09:04,313 DEBUG quic [0000000000000001] Network path ('127.0.0.1', 4987) promoted
2021-03-27 18:09:04,314 INFO quic [0000000000000001] HTTP request GET /index.html
2021-03-27 18:09:05,112 DEBUG quic [0000000000000001] Loss detection triggered
2021-03-27 18:09:05,112 DEBUG quic [0000000000000001] Sending PING (probe) in packet 8
2021-03-27 18:09:05,477 WARNING quic [0000000000000001] Error: 10, reason: Response does not match challenge, frame_type: 27
2021-03-27 18:09:05,478 DEBUG quic [0000000000000001] QuicConnectionState.CONNECTED -> QuicConnectionState.CLOSING
