2021-05-30 10:57:32,452 DEBUG asyncio Using selector: EpollSelector
2021-05-30 10:57:32,466 DEBUG quic [5e2b8a2c5fd902e0] TLS State.CLIENT_HANDSHAKE_START -> State.CLIENT_EXPECT_SERVER_HELLO
2021-05-30 10:57:32,968 DEBUG quic [5e2b8a2c5fd902e0] Loss detection triggered
2021-05-30 10:57:33,002 DEBUG quic [5e2b8a2c5fd902e0] QuicConnectionState.FIRSTFLIGHT -> QuicConnectionState.CONNECTED
2021-05-30 10:57:33,005 DEBUG quic [5e2b8a2c5fd902e0] TLS State.CLIENT_EXPECT_SERVER_HELLO -> State.CLIENT_EXPECT_ENCRYPTED_EXTENSIONS
2021-05-30 10:57:33,547 DEBUG quic [5e2b8a2c5fd902e0] TLS State.CLIENT_EXPECT_ENCRYPTED_EXTENSIONS -> State.CLIENT_EXPECT_CERTIFICATE_REQUEST_OR_CERTIFICATE
2021-05-30 10:57:33,548 DEBUG quic [5e2b8a2c5fd902e0] TLS State.CLIENT_EXPECT_CERTIFICATE_REQUEST_OR_CERTIFICATE -> State.CLIENT_EXPECT_CERTIFICATE_VERIFY
2021-05-30 10:57:33,549 DEBUG quic [5e2b8a2c5fd902e0] TLS State.CLIENT_EXPECT_CERTIFICATE_VERIFY -> State.CLIENT_EXPECT_FINISHED
2021-05-30 10:57:33,553 DEBUG quic [5e2b8a2c5fd902e0] TLS State.CLIENT_EXPECT_FINISHED -> State.CLIENT_POST_HANDSHAKE
2021-05-30 10:57:33,554 WARNING quic [5e2b8a2c5fd902e0] Error: 8, reason: original_destination_connection_id does not match, frame_type: QuicFrameType.CRYPTO
2021-05-30 10:57:33,555 DEBUG quic [5e2b8a2c5fd902e0] QuicConnectionState.CONNECTED -> QuicConnectionState.CLOSING
2021-05-30 10:57:35,055 DEBUG quic [5e2b8a2c5fd902e0] Discarding epoch Epoch.INITIAL
2021-05-30 10:57:35,056 DEBUG quic [5e2b8a2c5fd902e0] Discarding epoch Epoch.HANDSHAKE
2021-05-30 10:57:35,057 DEBUG quic [5e2b8a2c5fd902e0] Discarding epoch Epoch.ONE_RTT
2021-05-30 10:57:35,057 DEBUG quic [5e2b8a2c5fd902e0] QuicConnectionState.CLOSING -> QuicConnectionState.TERMINATED
Traceback (most recent call last):
  File "examples/http3_client.py", line 465, in <module>
    zero_rtt=args.zero_rtt,
  File "/usr/lib/python3.6/asyncio/base_events.py", line 484, in run_until_complete
    return future.result()
  File "examples/http3_client.py", line 313, in run
    wait_connected=not zero_rtt,
  File "/home/chris/TVOQE_UPGRADE_27/quic/aioquic/src/aioquic/asyncio/compat.py", line 17, in __aenter__
    return await self.gen.__anext__()
  File "/home/chris/TVOQE_UPGRADE_27/quic/aioquic/src/aioquic/asyncio/client.py", line 89, in connect
    await protocol.wait_connected()
  File "/home/chris/TVOQE_UPGRADE_27/quic/aioquic/src/aioquic/asyncio/protocol.py", line 127, in wait_connected
    await asyncio.shield(self._connected_waiter)
ConnectionError
