2021-05-22 13:02:04,254 DEBUG asyncio Using selector: EpollSelector
2021-05-22 13:02:04,263 DEBUG quic [35e7c38190917c80] TLS State.CLIENT_HANDSHAKE_START -> State.CLIENT_EXPECT_SERVER_HELLO
2021-05-22 13:02:04,491 DEBUG quic [35e7c38190917c80] QuicConnectionState.FIRSTFLIGHT -> QuicConnectionState.CONNECTED
2021-05-22 13:02:04,493 DEBUG quic [35e7c38190917c80] TLS State.CLIENT_EXPECT_SERVER_HELLO -> State.CLIENT_EXPECT_ENCRYPTED_EXTENSIONS
2021-05-22 13:02:04,599 DEBUG quic [35e7c38190917c80] TLS State.CLIENT_EXPECT_ENCRYPTED_EXTENSIONS -> State.CLIENT_EXPECT_CERTIFICATE_REQUEST_OR_CERTIFICATE
2021-05-22 13:02:04,600 DEBUG quic [35e7c38190917c80] TLS State.CLIENT_EXPECT_CERTIFICATE_REQUEST_OR_CERTIFICATE -> State.CLIENT_EXPECT_CERTIFICATE_VERIFY
2021-05-22 13:02:04,601 DEBUG quic [35e7c38190917c80] TLS State.CLIENT_EXPECT_CERTIFICATE_VERIFY -> State.CLIENT_EXPECT_FINISHED
2021-05-22 13:02:04,603 DEBUG quic [35e7c38190917c80] TLS State.CLIENT_EXPECT_FINISHED -> State.CLIENT_POST_HANDSHAKE
2021-05-22 13:02:04,603 WARNING quic [35e7c38190917c80] Error: 8, reason: original_destination_connection_id does not match, frame_type: QuicFrameType.CRYPTO
2021-05-22 13:02:04,603 DEBUG quic [35e7c38190917c80] QuicConnectionState.CONNECTED -> QuicConnectionState.CLOSING
2021-05-22 13:02:06,104 DEBUG quic [35e7c38190917c80] Discarding epoch Epoch.INITIAL
2021-05-22 13:02:06,105 DEBUG quic [35e7c38190917c80] Discarding epoch Epoch.HANDSHAKE
2021-05-22 13:02:06,105 DEBUG quic [35e7c38190917c80] Discarding epoch Epoch.ONE_RTT
2021-05-22 13:02:06,106 DEBUG quic [35e7c38190917c80] QuicConnectionState.CLOSING -> QuicConnectionState.TERMINATED
Traceback (most recent call last):
  File "examples/http3_client.py", line 465, in <module>
    zero_rtt=args.zero_rtt,
  File "/usr/lib/python3.6/asyncio/base_events.py", line 484, in run_until_complete
    return future.result()
  File "examples/http3_client.py", line 313, in run
    wait_connected=not zero_rtt,
  File "/quic/aioquic/src/aioquic/asyncio/compat.py", line 17, in __aenter__
    return await self.gen.__anext__()
  File "/quic/aioquic/src/aioquic/asyncio/client.py", line 89, in connect
    await protocol.wait_connected()
  File "/quic/aioquic/src/aioquic/asyncio/protocol.py", line 127, in wait_connected
    await asyncio.shield(self._connected_waiter)
ConnectionError
