2021-04-29 18:16:03,522 DEBUG asyncio Using selector: EpollSelector
2021-04-29 18:16:08,249 DEBUG quic [0000000000000002] Network path ('127.0.0.1', 4987) discovered
2021-04-29 18:16:08,252 DEBUG quic [0000000000000002] QuicConnectionState.FIRSTFLIGHT -> QuicConnectionState.CONNECTED
2021-04-29 18:16:08,267 DEBUG quic [0000000000000002] TLS State.SERVER_EXPECT_CLIENT_HELLO -> State.SERVER_EXPECT_FINISHED
2021-04-29 18:16:08,633 DEBUG quic [0000000000000002] Discarding epoch Epoch.INITIAL
2021-04-29 18:16:08,634 DEBUG quic [0000000000000002] TLS State.SERVER_EXPECT_FINISHED -> State.SERVER_POST_HANDSHAKE
2021-04-29 18:16:08,635 DEBUG quic [0000000000000002] Discarding epoch Epoch.HANDSHAKE
2021-04-29 18:16:08,635 INFO quic [0000000000000002] ALPN negotiated protocol hq-29
2021-04-29 18:16:08,635 DEBUG quic [0000000000000002] Network path ('127.0.0.1', 4987) validated by handshake
2021-04-29 18:16:08,885 DEBUG quic [0000000000000002] Stream 12 created by peer
2021-04-29 18:16:08,886 INFO quic [0000000000000002] Connection close code 0x150F, reason 
2021-04-29 18:16:08,886 DEBUG quic [0000000000000002] QuicConnectionState.CONNECTED -> QuicConnectionState.DRAINING
2021-04-29 18:16:08,886 INFO quic [0000000000000002] HTTP request GET /index.html
2021-04-29 18:16:10,387 DEBUG quic [0000000000000002] Discarding epoch Epoch.ONE_RTT
2021-04-29 18:16:10,387 DEBUG quic [0000000000000002] QuicConnectionState.DRAINING -> QuicConnectionState.TERMINATED
2021-04-29 18:16:11,202 DEBUG quic [4475ebe765aa5508] Network path ('127.0.0.1', 4987) discovered
2021-04-29 18:16:11,221 DEBUG quic [4475ebe765aa5508] Payload decryption failed
2021-04-29 18:16:12,502 ERROR asyncio Exception in callback _SelectorDatagramTransport._read_ready()
handle: <Handle _SelectorDatagramTransport._read_ready()>
Traceback (most recent call last):
  File "/usr/lib/python3.6/asyncio/events.py", line 145, in _run
    self._callback(*self._args)
  File "/usr/lib/python3.6/asyncio/selector_events.py", line 1068, in _read_ready
    self._protocol.datagram_received(data, addr)
  File "/quic/aioquic/src/aioquic/asyncio/server.py", line 149, in datagram_received
    protocol.datagram_received(data, addr)
  File "/quic/aioquic/src/aioquic/asyncio/protocol.py", line 135, in datagram_received
    self._quic.receive_datagram(cast(bytes, data), addr, now=self._loop.time())
  File "/quic/aioquic/src/aioquic/quic/connection.py", line 793, in receive_datagram
    ), "first packet must be INITIAL"
AssertionError: first packet must be INITIAL
2021-04-29 18:16:13,590 DEBUG quic [0000000000000002] Network path ('127.0.0.1', 4987) discovered
2021-04-29 18:16:13,591 DEBUG quic [0000000000000002] QuicConnectionState.FIRSTFLIGHT -> QuicConnectionState.CONNECTED
2021-04-29 18:16:13,591 INFO quic [0000000000000002] Connection close code 0x2827, reason 
2021-04-29 18:16:13,591 DEBUG quic [0000000000000002] QuicConnectionState.CONNECTED -> QuicConnectionState.DRAINING
2021-04-29 18:16:13,592 INFO quic [0000000000000002] Connection close code 0x158, reason 
2021-04-29 18:16:13,592 DEBUG quic [0000000000000002] QuicConnectionState.DRAINING -> QuicConnectionState.DRAINING
