2021-06-02 11:34:40,501 DEBUG asyncio Using selector: EpollSelector
2021-06-02 11:34:40,506 DEBUG quic [269c424d9a9bd0b1] TLS State.CLIENT_HANDSHAKE_START -> State.CLIENT_EXPECT_SERVER_HELLO
2021-06-02 11:34:40,784 DEBUG quic [269c424d9a9bd0b1] Decryption key is not available
2021-06-02 11:34:40,900 DEBUG quic [269c424d9a9bd0b1] Decryption key is not available
2021-06-02 11:34:41,008 DEBUG quic [269c424d9a9bd0b1] Loss detection triggered
2021-06-02 11:34:41,075 DEBUG quic [269c424d9a9bd0b1] Decryption key is not available
2021-06-02 11:34:41,195 DEBUG quic [269c424d9a9bd0b1] Decryption key is not available
2021-06-02 11:34:41,754 DEBUG quic [269c424d9a9bd0b1] Decryption key is not available
2021-06-02 11:34:42,009 DEBUG quic [269c424d9a9bd0b1] Loss detection triggered
2021-06-02 11:34:42,269 DEBUG quic [269c424d9a9bd0b1] Decryption key is not available
2021-06-02 11:34:42,459 DEBUG quic [269c424d9a9bd0b1] QuicConnectionState.FIRSTFLIGHT -> QuicConnectionState.CONNECTED
2021-06-02 11:34:42,460 DEBUG quic [269c424d9a9bd0b1] TLS State.CLIENT_EXPECT_SERVER_HELLO -> State.CLIENT_EXPECT_ENCRYPTED_EXTENSIONS
2021-06-02 11:34:42,681 WARNING quic [269c424d9a9bd0b1] Error: 10, reason: Unexpected frame type, frame_type: 30
2021-06-02 11:34:42,681 DEBUG quic [269c424d9a9bd0b1] QuicConnectionState.CONNECTED -> QuicConnectionState.CLOSING
2021-06-02 11:34:44,182 DEBUG quic [269c424d9a9bd0b1] Discarding epoch Epoch.INITIAL
2021-06-02 11:34:44,182 DEBUG quic [269c424d9a9bd0b1] Discarding epoch Epoch.HANDSHAKE
2021-06-02 11:34:44,182 DEBUG quic [269c424d9a9bd0b1] Discarding epoch Epoch.ONE_RTT
2021-06-02 11:34:44,182 DEBUG quic [269c424d9a9bd0b1] QuicConnectionState.CLOSING -> QuicConnectionState.TERMINATED
Traceback (most recent call last):
  File "examples/http3_client.py", line 465, in <module>
    zero_rtt=args.zero_rtt,
  File "/usr/lib/python3.6/asyncio/base_events.py", line 484, in run_until_complete
    return future.result()
  File "examples/http3_client.py", line 313, in run
    wait_connected=not zero_rtt,
  File "/home/chris/TVOQE_UPGRADE_27/quic/aioquic/src/aioquic/asyncio/compat.py", line 17, in __aenter__
    return await self.gen.__anext__()
  File "/home/chris/TVOQE_UPGRADE_27/quic/aioquic/src/aioquic/asyncio/client.py", line 89, in connect
    await protocol.wait_connected()
  File "/home/chris/TVOQE_UPGRADE_27/quic/aioquic/src/aioquic/asyncio/protocol.py", line 127, in wait_connected
    await asyncio.shield(self._connected_waiter)
ConnectionError
